Workbook

Sheet README
A1: McCahill & Co. — Cash Position & Planning Model
A2: Paste your bank data into TRANSACTIONS. Everything else calculates. Nothing here is filled with real numbers yet.
B4: HOW TO USE THIS
B5: Step 1 | C5: ACCOUNT MAP — list every account you have and say which entity owns it. Enter the balance immediately before Feb 1. Nothing works until this is done.
B6: Step 2 | C6: TRANSACTIONS — paste every bank line from every account. One row per transaction. Money IN is positive, money OUT is negative.
B7: Step 3 | C7: TRANSACTIONS column F — pick a category for each row from the dropdown. This is the only real work. Anything you are unsure of, pick '! UNCLEAR - NEEDS REVIEW'.
B8: Step 4 | C8: TRANSACTIONS column H — for any transfer between your own accounts, put the SAME pair id (T1, T2, T3...) on both sides. This is what stops transfers being counted as income.
B9: Step 5 | C9: Read CASH RECONCILIATION. If ending cash does not match your real bank balance, the gap is listed on FLAGS. Fix it there, do not force it.
B11: COLOUR CODE
B12: Yellow fill | C12: You fill this in.
B13: Blue text | C13: A number you typed. Change it freely.
B14: Black text | C14: A formula. Do not overwrite it.
B15: Green text | C15: Pulled from another tab.
B17: THE RULES THIS MODEL ENFORCES
B18: Transfers | C18: Money moved between your own accounts is never revenue and never an expense. It changes ending cash only.
B19: GST | C19: GST collected is not revenue. It is money you are holding for CRA. Enter it in column J and it is stripped out of the revenue figures.
B20: Receivables | C20: Unpaid invoices are not cash. Only money that has actually landed in an account belongs in TRANSACTIONS.
B21: Non-cash assets | C21: Vehicles, equipment, tools and inventory are not liquid cash. They appear in planning, never in the cash total.
B22: Cash is not profit | C22: Ending cash reflects loan payments, owner draws, GST timing and equipment purchases. BUSINESS PERFORMANCE shows the difference.
B23: Entity separation | C23: Sole prop (Feb 1 - Jun 30) and corporation (Jul 1 - Jan 31) are never combined. They are legally different taxpayers.
B25: TABS
B26: ACCOUNT MAP | C26: Your accounts, their entity, and opening balances.
B27: CATEGORIES | C27: The category list and what each one counts as. Reference only.
B28: TRANSACTIONS | C28: Where your data goes.
B29: CASH RECONCILIATION | C29: Opening + in - out = closing, per entity. The core check.
B30: MONTH BY MONTH | C30: Feb through Jan, split sole prop / corp / personal.
B31: BUSINESS PERFORMANCE | C31: Sole prop vs corporation, GST stripped out.
B32: CASH QUALITY | C32: Burn rate, runway, tax reserve, deployable capital.
B33: VEHICLE SCENARIOS | C33: What a $20k / $30k / $40k / $50k purchase does to your reserves.
B34: SCENARIOS | C34: Conservative / base / aggressive for next season.
B35: FLAGS | C35: Everything that does not tie, is uncategorised, or needs your answer.

Sheet ASSUMPTIONS
A1: Assumptions & Rates
A2: Blue cells are levers — change them and the whole model moves. Anything marked VERIFY must be checked against the current CRA figure before you rely on it.
A4: # | B4: Assumption | C4: Value | D4: Status | E4: Where it came from / what to check
A5: 1 | B5: Business start date | C5: 2026-02-01 | D5: Confirmed | E5: You confirmed Feb 2026 is the start of operations.
A6: 2 | B6: Sole prop period ends | C6: 2026-06-30 | D6: Confirmed
A7: 3 | B7: Corporation period starts | C7: 2026-07-01 | D7: Confirmed
A8: 4 | B8: Corporate fiscal year end | C8: 2027-01-31 | D8: Your choice | E8: You chose Jan 31. Confirm this is what was actually filed — it is set at incorporation and drives every tax deadline.
A9: 5 | B9: Crew wage — Kierran | C9: 27 | D9: Confirmed | E9: You confirmed $27.00/hr.
A10: 6 | B10: Owner draw from corporation, per month | C10: 4000 | D10: Confirmed | E10: You confirmed $4,000/month since July 1. Currently a shareholder loan unless declared as salary or dividend.
A11: 7 | B11: GST rate | C11: 0.05 | D11: Confirmed | E11: BC — GST only on landscaping services. No PST on the service itself.
A12: 8 | B12: CPP contribution rate (employee) | C12: 0.0595 | D12: VERIFY | E12: 2025 rate shown. Confirm the 2026 rate at canada.ca before relying on the liability estimate.
A13: 9 | B13: CPP basic exemption (annual) | C13: 3500 | D13: VERIFY | E13: 2025 figure. Confirm 2026.
A14: 10 | B14: EI premium rate (employee) | C14: 0.0164 | D14: VERIFY | E14: 2025 rate. Confirm 2026.
A15: 11 | B15: EI employer multiplier | C15: 1.4 | D15: VERIFY | E15: Employer pays 1.4x the employee premium. Confirm.
A16: 12 | B16: Income tax withheld — estimated rate | C16: 0.12 | D16: ESTIMATE | E16: A rough blended rate for a BC employee at this wage. Replace with the actual figure from your payroll calculation.
A17: 13 | B17: Late remittance penalty rate | C17: 0.1 | D17: ESTIMATE | E17: CRA charges 10% on a first failure to remit, 20% if repeated or grossly negligent. Interest accrues on top.
A18: 14 | B18: Corporate small business tax rate (BC) | C18: 0.11 | D18: ESTIMATE | E18: Roughly 9% federal + 2% BC on active business income under the small business limit. Confirm with your accountant.
A19: 15 | B19: Personal tax reserve rate (sole prop income) | C19: 0.25 | D19: ESTIMATE | E19: A holding rate until your actual return is prepared. Your real rate depends on total income and credits.
A20: 16 | B20: Target operating reserve (months) | C20: 3 | D20: Your lever | E20: Months of payroll plus fixed costs to keep untouched. 3 is a common floor for seasonal trades.
A21: 17 | B21: Months of the year that generate revenue | C21: 9 | D21: Your lever | E21: Landscaping in Victoria. Drives the winter burn calculation.

Sheet ACCOUNT MAP
A1: Account Map
A2: Every account you hold. Yellow cells are yours to fill. The entity you assign here drives the entire model.
A4: Account name (use this exact name in TRANSACTIONS) | B4: Bank / institution | C4: Entity | D4: Account type | E4: Balance immediately before Feb 1 | F4: Liquid? | G4: Notes
A5: EXAMPLE - BMO Business Chq 1234 | B5: BMO | C5: Sole Prop | D5: Chequing | E5: 0 | F5: Yes | G5: Delete this row once you add your own
A6: EQ - Sole Prop Chequing | B6: EQ Bank | C6: Sole Prop | D6: Chequing | E6: 0 | F6: Yes | G6: Statements Feb 9 - Aug 31, 2026 loaded. Opening balance $0.00 - first transaction Feb 9 established the account.
A7: EQ - Corporation Chequing | B7: EQ Bank | C7: Corporation | D7: Chequing | E7: 0 | F7: Yes | G7: Statement Aug 28 - Aug 31, 2026 loaded. Account opened Aug 28, NOT July 1.
A8: TD - Personal Chequing | B8: TD | C8: Personal | D8: Chequing | F8: Yes | G8: ENTER your TD balance as at Jan 31, 2026.
A9: Wealthsimple - Investments | B9: Wealthsimple | C9: Personal | D9: Investment | F9: Partly | G9: ENTER balance at Jan 31, 2026. Set Liquid to Yes only if you would genuinely sell. Confirm registered vs non-registered.
A46: OPENING CASH BEFORE FEB 1
A47: Personal | E47: =SUMIFS($E$6:$E$44,$C$6:$C$44,$A47,$F$6:$F$44,"Yes")
A48: Sole Prop | E48: =SUMIFS($E$6:$E$44,$C$6:$C$44,$A48,$F$6:$F$44,"Yes")
A49: Corporation | E49: =SUMIFS($E$6:$E$44,$C$6:$C$44,$A49,$F$6:$F$44,"Yes")
A50: TOTAL OPENING LIQUID CASH | E50: =SUM(E47:E49)
A52: Only accounts marked Liquid = "Yes" count toward cash. Mark a locked-in GIC or an RRSP you would not actually draw on as "No".

Sheet CATEGORIES
A1: Categories
A2: Reference. Column C is what the model does with each category. Do not rename anything here — TRANSACTIONS looks these up by exact text.
A4: # | B4: Category (appears in the TRANSACTIONS dropdown) | C4: Treated as | D4: What it means
A5: 1 | B5: Client payment received | C5: Revenue | D5: Money from a customer that actually landed. Enter GST separately in column J.
A6: 2 | B6: Deposit received (work not yet done) | C6: Revenue | D6: Cash you hold but have not earned. Real cash, but do not treat it as profit.
A7: 3 | B7: Other business income | C7: Revenue | D7: Rebates, insurance proceeds, equipment sold.
A8: 4 | B8: Materials and plants | C8: COGS | D8: Supplier purchases that go into a job.
A9: 5 | B9: Subcontractor | C9: COGS | D9: Paid to another business for job work.
A10: 6 | B10: Equipment rental | C10: COGS | D10: Rented for a specific job.
A11: 7 | B11: Disposal and dump fees | C11: COGS | D11: Tipping fees, debris hauling.
A12: 8 | B12: Fuel | C12: Operating Expense | D12: All vehicle fuel.
A13: 9 | B13: Vehicle repairs and maintenance | C13: Operating Expense | D13: Parts, service, tires.
A14: 10 | B14: Vehicle insurance | C14: Operating Expense | D14: ICBC and commercial coverage.
A15: 11 | B15: Liability insurance | C15: Operating Expense | D15: General business liability.
A16: 12 | B16: WorkSafeBC premiums | C16: Operating Expense | D16: Statutory coverage.
A17: 13 | B17: Rent, yard or storage | C17: Operating Expense | D17: Fixed premises cost.
A18: 14 | B18: Phone and internet | C18: Operating Expense
A19: 15 | B19: Software and subscriptions | C19: Operating Expense
A20: 16 | B20: Accounting and bookkeeping | C20: Operating Expense
A21: 17 | B21: Legal | C21: Operating Expense
A22: 18 | B22: Advertising and marketing | C22: Operating Expense
A23: 19 | B23: Bank and merchant fees | C23: Operating Expense | D23: Includes card processing fees.
A24: 20 | B24: Small tools and consumables | C24: Operating Expense | D24: Under the capitalisation threshold.
A25: 21 | B25: Other operating expense | C25: Operating Expense | D25: Use sparingly. A large balance here weakens the analysis.
A26: 22 | B26: Crew wages (net pay out) | C26: Payroll | D26: Net amount that left the bank to crew.
A27: 23 | B27: Payroll service fees | C27: Payroll
A28: 24 | B28: CRA source deductions remitted | C28: Tax/Remittance | D28: CPP, EI and income tax sent to CRA.
A29: 25 | B29: GST remitted to CRA | C29: Tax/Remittance | D29: Never an expense. You were holding this money.
A30: 26 | B30: Personal tax instalment | C30: Tax/Remittance | D30: Paid from whichever account it actually left.
A31: 27 | B31: Corporate tax instalment | C31: Tax/Remittance
A32: 28 | B32: Owner draw (sole prop) | C32: Owner Draw/Comp | D32: Not an expense. Reduces cash, not profit.
A33: 29 | B33: Owner salary (corporation) | C33: Owner Draw/Comp | D33: Through payroll, with source deductions.
A34: 30 | B34: Dividend paid to owner | C34: Owner Draw/Comp
A35: 31 | B35: Shareholder loan repaid to owner | C35: Owner Draw/Comp | D35: Money the corporation owed you, returned.
A36: 32 | B36: Vehicle purchase | C36: Capital Purchase | D36: Cash out now, expensed over years. A major cash-vs-profit gap.
A37: 33 | B37: Equipment purchase | C37: Capital Purchase | D37: Same treatment as a vehicle.
A38: 34 | B38: Loan or lease payment | C38: Financing | D38: The principal portion is not an expense.
A39: 35 | B39: Loan or financing proceeds | C39: Financing | D39: Cash in, but it is debt, not income.
A40: 36 | B40: Capital contributed by owner | C40: Financing | D40: Your money into the business. Never revenue.
A41: 37 | B41: Transfer - Personal <-> Sole Prop | C41: Transfer | D41: Excluded from revenue and expenses. Pair it in column H.
...

Sheet TRANSACTIONS
A1: Transactions
A2: Paste every bank line here, every account. Money IN positive, money OUT negative. Fill the yellow columns; grey columns calculate themselves.
B3: Type an account name EXACTLY as spelled on ACCOUNT MAP | F3: Type a category EXACTLY as spelled on the CATEGORIES tab
A4: Date | B4: Account (must match ACCOUNT MAP) | C4: Description from statement | D4: Amount (+ in / - out) | E4: Entity | F4: Category (pick from list) | G4: Treated as | H4: Transfer pair id | I4: GST included in this line | J4: Month key | K4: Your note
A5: 46062 | B5: EQ - Sole Prop Chequing | C5: Interac e-Transfer received from KYLE JOHN BENJAMIN MCCAHILL | D5: 100 | E5: =IF($B5="","",IFERROR(INDEX('ACCOUNT MAP'!$C$6:$C$44,MATCH($B5,'ACCOUNT MAP'!$A$6:$A$44,0)),"! UNMAPPED ACCOUNT")) | F5: Capital contributed by owner | G5: =IF($F5="","",IFERROR(INDEX(CATEGORIES!$C$5:$C$49,MATCH($F5,CATEGORIES!$B$5:$B$49,0)),"! UNKNOWN CATEGORY")) | J5: =IF($A5="","",YEAR($A5)*100+MONTH($A5))
A6: 46063 | B6: EQ - Sole Prop Chequing | C6: Interac e-Transfer received from KYLE JOHN BENJAMIN MCCAHILL | D6: 1500 | E6: =IF($B6="","",IFERROR(INDEX('ACCOUNT MAP'!$C$6:$C$44,MATCH($B6,'ACCOUNT MAP'!$A$6:$A$44,0)),"! UNMAPPED ACCOUNT")) | F6: Capital contributed by owner | G6: =IF($F6="","",IFERROR(INDEX(CATEGORIES!$C$5:$C$49,MATCH($F6,CATEGORIES!$B$5:$B$49,0)),"! UNKNOWN CATEGORY")) | J6: =IF($A6="","",YEAR($A6)*100+MONTH($A6))
A7: 46064 | B7: EQ - Sole Prop Chequing | C7: Interac e-Transfer received from PACIFIC CITY DEVELOPMENTS INC. | D7: 3490 | E7: =IF($B7="","",IFERROR(INDEX('ACCOUNT MAP'!$C$6:$C$44,MATCH($B7,'ACCOUNT MAP'!$A$6:$A$44,0)),"! UNMAPPED ACCOUNT")) | F7: Client payment received | G7: =IF($F7="","",IFERROR(INDEX(CATEGORIES!$C$5:$C$49,MATCH($F7,CATEGORIES!$B$5:$B$49,0)),"! UNKNOWN CATEGORY")) | I7: 166.19 | J7: =IF($A7="","",YEAR($A7)*100+MONTH($A7))
A8: 46068 | B8: EQ - Sole Prop Chequing | C8: Mobile cheque deposit | D8: 7500 | E8: =IF($B8="","",IFERROR(INDEX('ACCOUNT MAP'!$C$6:$C$44,MATCH($B8,'ACCOUNT MAP'!$A$6:$A$44,0)),"! UNMAPPED ACCOUNT")) | F8: Client payment received | G8: =IF($F8="","",IFERROR(INDEX(CATEGORIES!$C$5:$C$49,MATCH($F8,CATEGORIES!$B$5:$B$49,0)),"! UNKNOWN CATEGORY")) | I8: 357.14 | J8: =IF($A8="","",YEAR($A8)*100+MONTH($A8))
A9: 46069 | B9: EQ - Sole Prop Chequing | C9: Mobile cheque deposit | D9: 12500 | E9: =IF($B9="","",IFERROR(INDEX('ACCOUNT MAP'!$C$6:$C$44,MATCH($B9,'ACCOUNT MAP'!$A$6:$A$44,0)),"! UNMAPPED ACCOUNT")) | F9: Client payment received | G9: =IF($F9="","",IFERROR(INDEX(CATEGORIES!$C$5:$C$49,MATCH($F9,CATEGORIES!$B$5:$B$49,0)),"! UNKNOWN CATEGORY")) | I9: 595.24 | J9: =IF($A9="","",YEAR($A9)*100+MONTH($A9))
A10: 46076 | B10: EQ - Sole Prop Chequing | C10: Interac e-Transfer sent to PND GRAVEL MART | D10: -560 | E10: =IF($B10="","",IFERROR(INDEX('ACCOUNT MAP'!$C$6:$C$44,MATCH($B10,'ACCOUNT MAP'!$A$6:$A$44,0)),"! UNMAPPED ACCOUNT")) | F10: Materials and plants | G10: =IF($F10="","",IFERROR(INDEX(CATEGORIES!$C$5:$C$49,MATCH($F10,CATEGORIES!$B$5:$B$49,0)),"! UNKNOWN CATEGORY")) | J10: =IF($A10="","",YEAR($A10)*100+MONTH($A10))
A11: 46078 | B11: EQ - Sole Prop Chequing | C11: Mobile cheque deposit | D11: 3526.39 | E11: =IF($B11="","",IFERROR(INDEX('ACCOUNT MAP'!$C$6:$C$44,MATCH($B11,'ACCOUNT MAP'!$A$6:$A$44,0)),"! UNMAPPED ACCOUNT")) | F11: Client payment received | G11: =IF($F11="","",IFERROR(INDEX(CATEGORIES!$C$5:$C$49,MATCH($F11,CATEGORIES!$B$5:$B$49,0)),"! UNKNOWN CATEGORY")) | I11: 167.92 | J11: =IF($A11="","",YEAR($A11)*100+MONTH($A11))
A12: 46078 | B12: EQ - Sole Prop Chequing | C12: Interac e-Transfer sent to K2 Stone | D12: -7284.72 | E12: =IF($B12="","",IFERROR(INDEX('ACCOUNT MAP'!$C$6:$C$44,MATCH($B12,'ACCOUNT MAP'!$A$6:$A$44,0)),"! UNMAPPED ACCOUNT")) | F12: Materials and plants | G12: =IF($F12="","",IFERROR(INDEX(CATEGORIES!$C$5:$C$49,MATCH($F12,CATEGORIES!$B$5:$B$49,0)),"! UNKNOWN CATEGORY")) | J12: =IF($A12="","",YEAR($A12)*100+MONTH($A12))
A13: 46078 | B13: EQ - Sole Prop Chequing | C13: Interac e-Transfer sent to Myles (YGGDRASIL HORTICUL | D13: -1020 | E13: =IF($B13="","",IFERROR(INDEX('ACCOUNT MAP'!$C$6:$C$44,MATCH($B13,'ACCOUNT MAP'!$A$6:$A$44,0)),"! UNMAPPED ACCOUNT")) | F13: Materials and plants | G13: =IF($F13="","",IFERROR(INDEX(CATEGORIES!$C$5:$C$49,MATCH($F13,CATEGORIES!$B$5:$B$49,0)),"! UNKNOWN CATEGORY")) | J13: =IF($A13="","",YEAR($A13)*100+MONTH($A13))
A14: 46079 | B14: EQ - Sole Prop Chequing | C14: Mobile cheque deposit | D14: 10000 | E14: =IF($B14="","",IFERROR(INDEX('ACCOUNT MAP'!$C$6:$C$44,MATCH($B14,'ACCOUNT MAP'!$A$6:$A$44,0)),"! UNMAPPED ACCOUNT")) | F14: Client payment received | G14: =IF($F14="","",IFERROR(INDEX(CATEGORIES!$C$5:$C$49,MATCH($F14,CATEGORIES!$B$5:$B$49,0)),"! UNKNOWN CATEGORY")) | I14: 476.19 | J14: =IF($A14="","",YEAR($A14)*100+MONTH($A14))
A15: 46079 | B15: EQ - Sole Prop Chequing | C15: Interac e-Transfer sent to K2 Stone | D15: -2262.85 | E15: =IF($B15="","",IFERROR(INDEX('ACCOUNT MAP'!$C$6:$C$44,MATCH($B15,'ACCOUNT MAP'!$A$6:$A$44,0)),"! UNMAPPED ACCOUNT")) | F15: Materials and plants | G15: =IF($F15="","",IFERROR(INDEX(CATEGORIES!$C$5:$C$49,MATCH($F15,CATEGORIES!$B$5:$B$49,0)),"! UNKNOWN CATEGORY")) | J15: =IF($A15="","",YEAR($A15)*100+MONTH($A15))
A16: 46079 | B16: EQ - Sole Prop Chequing | C16: Interac e-Transfer sent to PND GRAVEL MART | D16: -280 | E16: =IF($B16="","",IFERROR(INDEX('ACCOUNT MAP'!$C$6:$C$44,MATCH($B16,'ACCOUNT MAP'!$A$6:$A$44,0)),"! UNMAPPED ACCOUNT")) | F16: Materials and plants | G16: =IF($F16="","",IFERROR(INDEX(CATEGORIES!$C$5:$C$49,MATCH($F16,CATEGORIES!$B$5:$B$49,0)),"! UNKNOWN CATEGORY")) | J16: =IF($A16="","",YEAR($A16)*100+MONTH($A16))
A17: 46079 | B17: EQ - Sole Prop Chequing | C17: Auto-withdrawal by AMEX BILL PYMT | D17: -1063.19 | E17: =IF($B17="","",IFERROR(INDEX('ACCOUNT MAP'!$C$6:$C$44,MATCH($B17,'ACCOUNT MAP'!$A$6:$A$44,0)),"! UNMAPPED ACCOUNT")) | F17: ! UNCLEAR - NEEDS REVIEW | G17: =IF($F17="","",IFERROR(INDEX(CATEGORIES!$C$5:$C$49,MATCH($F17,CATEGORIES!$B$5:$B$49,0)),"! UNKNOWN CATEGORY")) | J17: =IF($A17="","",YEAR($A17)*100+MONTH($A17)) | K17: Credit card payment — AMEX BILL PYMT
A18: 46081 | B18: EQ - Sole Prop Chequing | C18: Interest received | D18: 22.01 | E18: =IF($B18="","",IFERROR(INDEX('ACCOUNT MAP'!$C$6:$C$44,MATCH($B18,'ACCOUNT MAP'!$A$6:$A$44,0)),"! UNMAPPED ACCOUNT")) | F18: Other business income | G18: =IF($F18="","",IFERROR(INDEX(CATEGORIES!$C$5:$C$49,MATCH($F18,CATEGORIES!$B$5:$B$49,0)),"! UNKNOWN CATEGORY")) | J18: =IF($A18="","",YEAR($A18)*100+MONTH($A18))
A19: 46083 | B19: EQ - Sole Prop Chequing | C19: Interac e-Transfer sent to GC Excavation | D19: -2520 | E19: =IF($B19="","",IFERROR(INDEX('ACCOUNT MAP'!$C$6:$C$44,MATCH($B19,'ACCOUNT MAP'!$A$6:$A$44,0)),"! UNMAPPED ACCOUNT")) | F19: Subcontractor | G19: =IF($F19="","",IFERROR(INDEX(CATEGORIES!$C$5:$C$49,MATCH($F19,CATEGORIES!$B$5:$B$49,0)),"! UNKNOWN CATEGORY")) | J19: =IF($A19="","",YEAR($A19)*100+MONTH($A19))
A20: 46084 | B20: EQ - Sole Prop Chequing | C20: Interac e-Transfer sent to Michelle | D20: -5175 | E20: =IF($B20="","",IFERROR(INDEX('ACCOUNT MAP'!$C$6:$C$44,MATCH($B20,'ACCOUNT MAP'!$A$6:$A$44,0)),"! UNMAPPED ACCOUNT")) | F20: ! UNCLEAR - NEEDS REVIEW | G20: =IF($F20="","",IFERROR(INDEX(CATEGORIES!$C$5:$C$49,MATCH($F20,CATEGORIES!$B$5:$B$49,0)),"! UNKNOWN CATEGORY")) | J20: =IF($A20="","",YEAR($A20)*100+MONTH($A20)) | K20: ? Crew or sub — Michelle
A21: 46084 | B21: EQ - Sole Prop Chequing | C21: Interac e-Transfer sent to Canopyco | D21: -250 | E21: =IF($B21="","",IFERROR(INDEX('ACCOUNT MAP'!$C$6:$C$44,MATCH($B21,'ACCOUNT MAP'!$A$6:$A$44,0)),"! UNMAPPED ACCOUNT")) | F21: ! UNCLEAR - NEEDS REVIEW | G21: =IF($F21="","",IFERROR(INDEX(CATEGORIES!$C$5:$C$49,MATCH($F21,CATEGORIES!$B$5:$B$49,0)),"! UNKNOWN CATEGORY")) | J21: =IF($A21="","",YEAR($A21)*100+MONTH($A21)) | K21: ? Canopyco — UNIDENTIFIED
A22: 46088 | B22: EQ - Sole Prop Chequing | C22: Interac e-Transfer sent to Kierran Kivinen | D22: -435.42 | E22: =IF($B22="","",IFERROR(INDEX('ACCOUNT MAP'!$C$6:$C$44,MATCH($B22,'ACCOUNT MAP'!$A$6:$A$44,0)),"! UNMAPPED ACCOUNT")) | F22: Crew wages (net pay out) | G22: =IF($F22="","",IFERROR(INDEX(CATEGORIES!$C$5:$C$49,MATCH($F22,CATEGORIES!$B$5:$B$49,0)),"! UNKNOWN CATEGORY")) | J22: =IF($A22="","",YEAR($A22)*100+MONTH($A22))
A23: 46090 | B23: EQ - Sole Prop Chequing | C23: Mobile cheque deposit | D23: 1925.83 | E23: =IF($B23="","",IFERROR(INDEX('ACCOUNT MAP'!$C$6:$C$44,MATCH($B23,'ACCOUNT MAP'!$A$6:$A$44,0)),"! UNMAPPED ACCOUNT")) | F23: Client payment received | G23: =IF($F23="","",IFERROR(INDEX(CATEGORIES!$C$5:$C$49,MATCH($F23,CATEGORIES!$B$5:$B$49,0)),"! UNKNOWN CATEGORY")) | I23: 91.71 | J23: =IF($A23="","",YEAR($A23)*100+MONTH($A23))
A24: 46091 | B24: EQ - Sole Prop Chequing | C24: Mobile cheque deposit | D24: 1020.14 | E24: =IF($B24="","",IFERROR(INDEX('ACCOUNT MAP'!$C$6:$C$44,MATCH($B24,'ACCOUNT MAP'!$A$6:$A$44,0)),"! UNMAPPED ACCOUNT")) | F24: Client payment received | G24: =IF($F24="","",IFERROR(INDEX(CATEGORIES!$C$5:$C$49,MATCH($F24,CATEGORIES!$B$5:$B$49,0)),"! UNKNOWN CATEGORY")) | I24: 48.58 | J24: =IF($A24="","",YEAR($A24)*100+MONTH($A24))
A25: 46091 | B25: EQ - Sole Prop Chequing | C25: Mobile cheque deposit | D25: 1797.06 | E25: =IF($B25="","",IFERROR(INDEX('ACCOUNT MAP'!$C$6:$C$44,MATCH($B25,'ACCOUNT MAP'!$A$6:$A$44,0)),"! UNMAPPED ACCOUNT")) | F25: Client payment received | G25: =IF($F25="","",IFERROR(INDEX(CATEGORIES!$C$5:$C$49,MATCH($F25,CATEGORIES!$B$5:$B$49,0)),"! UNKNOWN CATEGORY")) | I25: 85.57 | J25: =IF($A25="","",YEAR($A25)*100+MONTH($A25))
A26: 46091 | B26: EQ - Sole Prop Chequing | C26: Auto-withdrawal by Wave PYRL | D26: -1105.7 | E26: =IF($B26="","",IFERROR(INDEX('ACCOUNT MAP'!$C$6:$C$44,MATCH($B26,'ACCOUNT MAP'!$A$6:$A$44,0)),"! UNMAPPED ACCOUNT")) | F26: Crew wages (net pay out) | G26: =IF($F26="","",IFERROR(INDEX(CATEGORIES!$C$5:$C$49,MATCH($F26,CATEGORIES!$B$5:$B$49,0)),"! UNKNOWN CATEGORY")) | J26: =IF($A26="","",YEAR($A26)*100+MONTH($A26))
A27: 46091 | B27: EQ - Sole Prop Chequing | C27: Interac e-Transfer sent to Canopyco | D27: -5000 | E27: =IF($B27="","",IFERROR(INDEX('ACCOUNT MAP'!$C$6:$C$44,MATCH($B27,'ACCOUNT MAP'!$A$6:$A$44,0)),"! UNMAPPED ACCOUNT")) | F27: ! UNCLEAR - NEEDS REVIEW | G27: =IF($F27="","",IFERROR(INDEX(CATEGORIES!$C$5:$C$49,MATCH($F27,CATEGORIES!$B$5:$B$49,0)),"! UNKNOWN CATEGORY")) | J27: =IF($A27="","",YEAR($A27)*100+MONTH($A27)) | K27: ? Canopyco — UNIDENTIFIED
A28: 46092 | B28: EQ - Sole Prop Chequing | C28: Mobile cheque deposit | D28: 10569.01 | E28: =IF($B28="","",IFERROR(INDEX('ACCOUNT MAP'!$C$6:$C$44,MATCH($B28,'ACCOUNT MAP'!$A$6:$A$44,0)),"! UNMAPPED ACCOUNT")) | F28: Client payment received | G28: =IF($F28="","",IFERROR(INDEX(CATEGORIES!$C$5:$C$49,MATCH($F28,CATEGORIES!$B$5:$B$49,0)),"! UNKNOWN CATEGORY")) | I28: 503.29 | J28: =IF($A28="","",YEAR($A28)*100+MONTH($A28))
A29: 46092 | B29: EQ - Sole Prop Chequing | C29: Mobile cheque deposit | D29: -10569.01 | E29: =IF($B29="","",IFERROR(INDEX('ACCOUNT MAP'!$C$6:$C$44,MATCH($B29,'ACCOUNT MAP'!$A$6:$A$44,0)),"! UNMAPPED ACCOUNT")) | F29: Client payment received | G29: =IF($F29="","",IFERROR(INDEX(CATEGORIES!$C$5:$C$49,MATCH($F29,CATEGORIES!$B$5:$B$49,0)),"! UNKNOWN CATEGORY")) | J29: =IF($A29="","",YEAR($A29)*100+MONTH($A29))
A30: 46093 | B30: EQ - Sole Prop Chequing | C30: Mobile cheque deposit | D30: 10569.01 | E30: =IF($B30="","",IFERROR(INDEX('ACCOUNT MAP'!$C$6:$C$44,MATCH($B30,'ACCOUNT MAP'!$A$6:$A$44,0)),"! UNMAPPED ACCOUNT")) | F30: Client payment received | G30: =IF($F30="","",IFERROR(INDEX(CATEGORIES!$C$5:$C$49,MATCH($F30,CATEGORIES!$B$5:$B$49,0)),"! UNKNOWN CATEGORY")) | I30: 503.29 | J30: =IF($A30="","",YEAR($A30)*100+MONTH($A30))
A31: 46093 | B31: EQ - Sole Prop Chequing | C31: Interac e-Transfer sent to PND GRAVEL MART | D31: -151.2 | E31: =IF($B31="","",IFERROR(INDEX('ACCOUNT MAP'!$C$6:$C$44,MATCH($B31,'ACCOUNT MAP'!$A$6:$A$44,0)),"! UNMAPPED ACCOUNT")) | F31: Materials and plants | G31: =IF($F31="","",IFERROR(INDEX(CATEGORIES!$C$5:$C$49,MATCH($F31,CATEGORIES!$B$5:$B$49,0)),"! UNKNOWN CATEGORY")) | J31: =IF($A31="","",YEAR($A31)*100+MONTH($A31))
A32: 46093 | B32: EQ - Sole Prop Chequing | C32: Interac e-Transfer sent to PND GRAVEL MART | D32: -112 | E32: =IF($B32="","",IFERROR(INDEX('ACCOUNT MAP'!$C$6:$C$44,MATCH($B32,'ACCOUNT MAP'!$A$6:$A$44,0)),"! UNMAPPED ACCOUNT")) | F32: Materials and plants | G32: =IF($F32="","",IFERROR(INDEX(CATEGORIES!$C$5:$C$49,MATCH($F32,CATEGORIES!$B$5:$B$49,0)),"! UNKNOWN CATEGORY")) | J32: =IF($A32="","",YEAR($A32)*100+MONTH($A32))
A33: 46093 | B33: EQ - Sole Prop Chequing | C33: Interac e-Transfer sent to PND GRAVEL MART | D33: -398.72 | E33: =IF($B33="","",IFERROR(INDEX('ACCOUNT MAP'!$C$6:$C$44,MATCH($B33,'ACCOUNT MAP'!$A$6:$A$44,0)),"! UNMAPPED ACCOUNT")) | F33: Materials and plants | G33: =IF($F33="","",IFERROR(INDEX(CATEGORIES!$C$5:$C$49,MATCH($F33,CATEGORIES!$B$5:$B$49,0)),"! UNKNOWN CATEGORY")) | J33: =IF($A33="","",YEAR($A33)*100+MONTH($A33))
A34: 46093 | B34: EQ - Sole Prop Chequing | C34: Interac e-Transfer sent to PND GRAVEL MART | D34: -1267.84 | E34: =IF($B34="","",IFERROR(INDEX('ACCOUNT MAP'!$C$6:$C$44,MATCH($B34,'ACCOUNT MAP'!$A$6:$A$44,0)),"! UNMAPPED ACCOUNT")) | F34: Materials and plants | G34: =IF($F34="","",IFERROR(INDEX(CATEGORIES!$C$5:$C$49,MATCH($F34,CATEGORIES!$B$5:$B$49,0)),"! UNKNOWN CATEGORY")) | J34: =IF($A34="","",YEAR($A34)*100+MONTH($A34))
A35: 46093 | B35: EQ - Sole Prop Chequing | C35: Mobile cheque deposit | D35: -10569.01 | E35: =IF($B35="","",IFERROR(INDEX('ACCOUNT MAP'!$C$6:$C$44,MATCH($B35,'ACCOUNT MAP'!$A$6:$A$44,0)),"! UNMAPPED ACCOUNT")) | F35: Client payment received | G35: =IF($F35="","",IFERROR(INDEX(CATEGORIES!$C$5:$C$49,MATCH($F35,CATEGORIES!$B$5:$B$49,0)),"! UNKNOWN CATEGORY")) | J35: =IF($A35="","",YEAR($A35)*100+MONTH($A35))
A36: 46096 | B36: EQ - Sole Prop Chequing | C36: Interac e-Transfer received from BEVERLY DEVRIES | D36: 840 | E36: =IF($B36="","",IFERROR(INDEX('ACCOUNT MAP'!$C$6:$C$44,MATCH($B36,'ACCOUNT MAP'!$A$6:$A$44,0)),"! UNMAPPED ACCOUNT")) | F36: Client payment received | G36: =IF($F36="","",IFERROR(INDEX(CATEGORIES!$C$5:$C$49,MATCH($F36,CATEGORIES!$B$5:$B$49,0)),"! UNKNOWN CATEGORY")) | I36: 40 | J36: =IF($A36="","",YEAR($A36)*100+MONTH($A36))
A37: 46096 | B37: EQ - Sole Prop Chequing | C37: Interac e-Transfer sent to Kierran Kivinen | D37: -622.29 | E37: =IF($B37="","",IFERROR(INDEX('ACCOUNT MAP'!$C$6:$C$44,MATCH($B37,'ACCOUNT MAP'!$A$6:$A$44,0)),"! UNMAPPED ACCOUNT")) | F37: Crew wages (net pay out) | G37: =IF($F37="","",IFERROR(INDEX(CATEGORIES!$C$5:$C$49,MATCH($F37,CATEGORIES!$B$5:$B$49,0)),"! UNKNOWN CATEGORY")) | J37: =IF($A37="","",YEAR($A37)*100+MONTH($A37))
A38: 46098 | B38: EQ - Sole Prop Chequing | C38: Auto-withdrawal by Gore Mutual | D38: -93.8 | E38: =IF($B38="","",IFERROR(INDEX('ACCOUNT MAP'!$C$6:$C$44,MATCH($B38,'ACCOUNT MAP'!$A$6:$A$44,0)),"! UNMAPPED ACCOUNT")) | F38: Liability insurance | G38: =IF($F38="","",IFERROR(INDEX(CATEGORIES!$C$5:$C$49,MATCH($F38,CATEGORIES!$B$5:$B$49,0)),"! UNKNOWN CATEGORY")) | J38: =IF($A38="","",YEAR($A38)*100+MONTH($A38))
A39: 46099 | B39: EQ - Sole Prop Chequing | C39: Mobile cheque deposit | D39: 11532 | E39: =IF($B39="","",IFERROR(INDEX('ACCOUNT MAP'!$C$6:$C$44,MATCH($B39,'ACCOUNT MAP'!$A$6:$A$44,0)),"! UNMAPPED ACCOUNT")) | F39: Client payment received | G39: =IF($F39="","",IFERROR(INDEX(CATEGORIES!$C$5:$C$49,MATCH($F39,CATEGORIES!$B$5:$B$49,0)),"! UNKNOWN CATEGORY")) | I39: 549.14 | J39: =IF($A39="","",YEAR($A39)*100+MONTH($A39))
A40: 46101 | B40: EQ - Sole Prop Chequing | C40: Interac e-Transfer received from PACIFIC CITY DEVELOPMENTS INC. | D40: 2136.79 | E40: =IF($B40="","",IFERROR(INDEX('ACCOUNT MAP'!$C$6:$C$44,MATCH($B40,'ACCOUNT MAP'!$A$6:$A$44,0)),"! UNMAPPED ACCOUNT")) | F40: Client payment received | G40: =IF($F40="","",IFERROR(INDEX(CATEGORIES!$C$5:$C$49,MATCH($F40,CATEGORIES!$B$5:$B$49,0)),"! UNKNOWN CATEGORY")) | I40: 101.75 | J40: =IF($A40="","",YEAR($A40)*100+MONTH($A40))
...

Sheet CASH RECONCILIATION
A1: Cash Reconciliation — Feb 1, 2026 to Jan 31, 2027
A2: Opening + inflows - outflows = closing, per entity. If the difference row is not zero, the data is incomplete. Do not force it — the gap is the finding.
A4: Line | B4: Personal | C4: Sole Prop | D4: Corporation | E4: TOTAL
A5: Opening cash immediately before Feb 1 | B5: ='ACCOUNT MAP'!$E$47 | C5: ='ACCOUNT MAP'!$E$48 | D5: ='ACCOUNT MAP'!$E$49 | E5: =SUM(B5:D5)
A6: Revenue collected (gross, includes GST) | B6: =SUMIFS(TRANSACTIONS!$D$5:$D$244,TRANSACTIONS!$E$5:$E$244,"Personal",TRANSACTIONS!$G$5:$G$244,"Revenue") | C6: =SUMIFS(TRANSACTIONS!$D$5:$D$244,TRANSACTIONS!$E$5:$E$244,"Sole Prop",TRANSACTIONS!$G$5:$G$244,"Revenue") | D6: =SUMIFS(TRANSACTIONS!$D$5:$D$244,TRANSACTIONS!$E$5:$E$244,"Corporation",TRANSACTIONS!$G$5:$G$244,"Revenue") | E6: =SUM(B6:D6)
A7: Personal income received | B7: =SUMIFS(TRANSACTIONS!$D$5:$D$244,TRANSACTIONS!$E$5:$E$244,"Personal",TRANSACTIONS!$G$5:$G$244,"Personal Income") | C7: =SUMIFS(TRANSACTIONS!$D$5:$D$244,TRANSACTIONS!$E$5:$E$244,"Sole Prop",TRANSACTIONS!$G$5:$G$244,"Personal Income") | D7: =SUMIFS(TRANSACTIONS!$D$5:$D$244,TRANSACTIONS!$E$5:$E$244,"Corporation",TRANSACTIONS!$G$5:$G$244,"Personal Income") | E7: =SUM(B7:D7)
A8: Financing proceeds / capital contributed | B8: =SUMIFS(TRANSACTIONS!$D$5:$D$244,TRANSACTIONS!$E$5:$E$244,"Personal",TRANSACTIONS!$G$5:$G$244,"Financing") | C8: =SUMIFS(TRANSACTIONS!$D$5:$D$244,TRANSACTIONS!$E$5:$E$244,"Sole Prop",TRANSACTIONS!$G$5:$G$244,"Financing") | D8: =SUMIFS(TRANSACTIONS!$D$5:$D$244,TRANSACTIONS!$E$5:$E$244,"Corporation",TRANSACTIONS!$G$5:$G$244,"Financing") | E8: =SUM(B8:D8)
A9: Investments bought and sold (net) | B9: =SUMIFS(TRANSACTIONS!$D$5:$D$244,TRANSACTIONS!$E$5:$E$244,"Personal",TRANSACTIONS!$G$5:$G$244,"Investment") | C9: =SUMIFS(TRANSACTIONS!$D$5:$D$244,TRANSACTIONS!$E$5:$E$244,"Sole Prop",TRANSACTIONS!$G$5:$G$244,"Investment") | D9: =SUMIFS(TRANSACTIONS!$D$5:$D$244,TRANSACTIONS!$E$5:$E$244,"Corporation",TRANSACTIONS!$G$5:$G$244,"Investment") | E9: =SUM(B9:D9)
A10: COGS and materials paid | B10: =SUMIFS(TRANSACTIONS!$D$5:$D$244,TRANSACTIONS!$E$5:$E$244,"Personal",TRANSACTIONS!$G$5:$G$244,"COGS") | C10: =SUMIFS(TRANSACTIONS!$D$5:$D$244,TRANSACTIONS!$E$5:$E$244,"Sole Prop",TRANSACTIONS!$G$5:$G$244,"COGS") | D10: =SUMIFS(TRANSACTIONS!$D$5:$D$244,TRANSACTIONS!$E$5:$E$244,"Corporation",TRANSACTIONS!$G$5:$G$244,"COGS") | E10: =SUM(B10:D10)
A11: Operating expenses paid | B11: =SUMIFS(TRANSACTIONS!$D$5:$D$244,TRANSACTIONS!$E$5:$E$244,"Personal",TRANSACTIONS!$G$5:$G$244,"Operating Expense") | C11: =SUMIFS(TRANSACTIONS!$D$5:$D$244,TRANSACTIONS!$E$5:$E$244,"Sole Prop",TRANSACTIONS!$G$5:$G$244,"Operating Expense") | D11: =SUMIFS(TRANSACTIONS!$D$5:$D$244,TRANSACTIONS!$E$5:$E$244,"Corporation",TRANSACTIONS!$G$5:$G$244,"Operating Expense") | E11: =SUM(B11:D11)
A12: Payroll paid | B12: =SUMIFS(TRANSACTIONS!$D$5:$D$244,TRANSACTIONS!$E$5:$E$244,"Personal",TRANSACTIONS!$G$5:$G$244,"Payroll") | C12: =SUMIFS(TRANSACTIONS!$D$5:$D$244,TRANSACTIONS!$E$5:$E$244,"Sole Prop",TRANSACTIONS!$G$5:$G$244,"Payroll") | D12: =SUMIFS(TRANSACTIONS!$D$5:$D$244,TRANSACTIONS!$E$5:$E$244,"Corporation",TRANSACTIONS!$G$5:$G$244,"Payroll") | E12: =SUM(B12:D12)
A13: Taxes and remittances paid | B13: =SUMIFS(TRANSACTIONS!$D$5:$D$244,TRANSACTIONS!$E$5:$E$244,"Personal",TRANSACTIONS!$G$5:$G$244,"Tax/Remittance") | C13: =SUMIFS(TRANSACTIONS!$D$5:$D$244,TRANSACTIONS!$E$5:$E$244,"Sole Prop",TRANSACTIONS!$G$5:$G$244,"Tax/Remittance") | D13: =SUMIFS(TRANSACTIONS!$D$5:$D$244,TRANSACTIONS!$E$5:$E$244,"Corporation",TRANSACTIONS!$G$5:$G$244,"Tax/Remittance") | E13: =SUM(B13:D13)
A14: Owner draws / compensation | B14: =SUMIFS(TRANSACTIONS!$D$5:$D$244,TRANSACTIONS!$E$5:$E$244,"Personal",TRANSACTIONS!$G$5:$G$244,"Owner Draw/Comp") | C14: =SUMIFS(TRANSACTIONS!$D$5:$D$244,TRANSACTIONS!$E$5:$E$244,"Sole Prop",TRANSACTIONS!$G$5:$G$244,"Owner Draw/Comp") | D14: =SUMIFS(TRANSACTIONS!$D$5:$D$244,TRANSACTIONS!$E$5:$E$244,"Corporation",TRANSACTIONS!$G$5:$G$244,"Owner Draw/Comp") | E14: =SUM(B14:D14)
A15: Capital purchases (vehicles, equipment) | B15: =SUMIFS(TRANSACTIONS!$D$5:$D$244,TRANSACTIONS!$E$5:$E$244,"Personal",TRANSACTIONS!$G$5:$G$244,"Capital Purchase") | C15: =SUMIFS(TRANSACTIONS!$D$5:$D$244,TRANSACTIONS!$E$5:$E$244,"Sole Prop",TRANSACTIONS!$G$5:$G$244,"Capital Purchase") | D15: =SUMIFS(TRANSACTIONS!$D$5:$D$244,TRANSACTIONS!$E$5:$E$244,"Corporation",TRANSACTIONS!$G$5:$G$244,"Capital Purchase") | E15: =SUM(B15:D15)
A16: Personal expenses paid | B16: =SUMIFS(TRANSACTIONS!$D$5:$D$244,TRANSACTIONS!$E$5:$E$244,"Personal",TRANSACTIONS!$G$5:$G$244,"Personal Expense") | C16: =SUMIFS(TRANSACTIONS!$D$5:$D$244,TRANSACTIONS!$E$5:$E$244,"Sole Prop",TRANSACTIONS!$G$5:$G$244,"Personal Expense") | D16: =SUMIFS(TRANSACTIONS!$D$5:$D$244,TRANSACTIONS!$E$5:$E$244,"Corporation",TRANSACTIONS!$G$5:$G$244,"Personal Expense") | E16: =SUM(B16:D16)
A17: INTER-ACCOUNT / INTER-ENTITY TRANSFERS (net) | B17: =SUMIFS(TRANSACTIONS!$D$5:$D$244,TRANSACTIONS!$E$5:$E$244,"Personal",TRANSACTIONS!$G$5:$G$244,"Transfer") | C17: =SUMIFS(TRANSACTIONS!$D$5:$D$244,TRANSACTIONS!$E$5:$E$244,"Sole Prop",TRANSACTIONS!$G$5:$G$244,"Transfer") | D17: =SUMIFS(TRANSACTIONS!$D$5:$D$244,TRANSACTIONS!$E$5:$E$244,"Corporation",TRANSACTIONS!$G$5:$G$244,"Transfer") | E17: =SUM(B17:D17)
A18: Unclassified — needs review | B18: =SUMIFS(TRANSACTIONS!$D$5:$D$244,TRANSACTIONS!$E$5:$E$244,"Personal",TRANSACTIONS!$G$5:$G$244,"Review") | C18: =SUMIFS(TRANSACTIONS!$D$5:$D$244,TRANSACTIONS!$E$5:$E$244,"Sole Prop",TRANSACTIONS!$G$5:$G$244,"Review") | D18: =SUMIFS(TRANSACTIONS!$D$5:$D$244,TRANSACTIONS!$E$5:$E$244,"Corporation",TRANSACTIONS!$G$5:$G$244,"Review") | E18: =SUM(B18:D18)
A19: CALCULATED ENDING CASH | B19: =SUM(B5:B18) | C19: =SUM(C5:C18) | D19: =SUM(D5:D18) | E19: =SUM(E5:E18)
A20: Actual bank balance at Jan 31 (you enter this) | C20: 67159.36 | D20: 32107.9 | E20: =SUM(B20:D20)
A21: DIFFERENCE — must be zero | B21: =B20-B19 | C21: =C20-C19 | D21: =D20-D19 | E21: =E20-E19
A23: A non-zero difference means one of: a missing statement month, a transaction you have not entered, an account missing from ACCOUNT MAP, or a wrong opening balance.
A24: Transfers net to roughly zero across the TOTAL column. If the total transfer line is materially non-zero, you have a transfer entered on one side only — that is the classic double-count.
A25: This reconciliation is the audit trail. Every figure elsewhere in this workbook depends on it balancing.

Sheet MONTH BY MONTH
A1: Month by Month — Feb 2026 through Jan 2027
A2: Signs are natural: money in is positive, money out is negative, so every row adds up to the net change. Transfers are excluded from the operating columns but included in ending cash.
A4: Month | B4: Month key | C4: Sole prop revenue (gross) | D4: less GST collected | E4: Sole prop revenue ex-GST | F4: Corp revenue (gross) | G4: less GST collected | H4: Corp revenue ex-GST | I4: COGS / materials | J4: Operating expenses | K4: Payroll | L4: Taxes and remittances | M4: Owner draws / comp | N4: Capital purchases | O4: Financing (net) | P4: Operating cash flow | Q4: Net business cash change | R4: Personal cash change | S4: Ending sole prop cash | T4: Ending corp cash | U4: Ending personal cash | V4: TOTAL LIQUID CASH
A5: Opening (Jan 31, 2026) | S5: ='ACCOUNT MAP'!$E$48 | T5: ='ACCOUNT MAP'!$E$49 | U5: ='ACCOUNT MAP'!$E$47 | V5: =SUM(S5:U5)
A6: Feb 2026 | B6: 202602 | C6: =SUMIFS(TRANSACTIONS!$D$5:$D$244,TRANSACTIONS!$E$5:$E$244,"Sole Prop",TRANSACTIONS!$G$5:$G$244,"Revenue",TRANSACTIONS!$J$5:$J$244,$B6) | D6: =-SUMIFS(TRANSACTIONS!$I$5:$I$244,TRANSACTIONS!$E$5:$E$244,"Sole Prop",TRANSACTIONS!$G$5:$G$244,"Revenue",TRANSACTIONS!$J$5:$J$244,$B6) | E6: =C6+D6 | F6: =SUMIFS(TRANSACTIONS!$D$5:$D$244,TRANSACTIONS!$E$5:$E$244,"Corporation",TRANSACTIONS!$G$5:$G$244,"Revenue",TRANSACTIONS!$J$5:$J$244,$B6) | G6: =-SUMIFS(TRANSACTIONS!$I$5:$I$244,TRANSACTIONS!$E$5:$E$244,"Corporation",TRANSACTIONS!$G$5:$G$244,"Revenue",TRANSACTIONS!$J$5:$J$244,$B6) | H6: =F6+G6 | I6: =(SUMIFS(TRANSACTIONS!$D$5:$D$244,TRANSACTIONS!$E$5:$E$244,"Sole Prop",TRANSACTIONS!$G$5:$G$244,"COGS",TRANSACTIONS!$J$5:$J$244,$B6)+SUMIFS(TRANSACTIONS!$D$5:$D$244,TRANSACTIONS!$E$5:$E$244,"Corporation",TRANSACTIONS!$G$5:$G$244,"COGS",TRANSACTIONS!$J$5:$J$244,$B6)) | J6: =(SUMIFS(TRANSACTIONS!$D$5:$D$244,TRANSACTIONS!$E$5:$E$244,"Sole Prop",TRANSACTIONS!$G$5:$G$244,"Operating Expense",TRANSACTIONS!$J$5:$J$244,$B6)+SUMIFS(TRANSACTIONS!$D$5:$D$244,TRANSACTIONS!$E$5:$E$244,"Corporation",TRANSACTIONS!$G$5:$G$244,"Operating Expense",TRANSACTIONS!$J$5:$J$244,$B6)) | K6: =(SUMIFS(TRANSACTIONS!$D$5:$D$244,TRANSACTIONS!$E$5:$E$244,"Sole Prop",TRANSACTIONS!$G$5:$G$244,"Payroll",TRANSACTIONS!$J$5:$J$244,$B6)+SUMIFS(TRANSACTIONS!$D$5:$D$244,TRANSACTIONS!$E$5:$E$244,"Corporation",TRANSACTIONS!$G$5:$G$244,"Payroll",TRANSACTIONS!$J$5:$J$244,$B6)) | L6: =(SUMIFS(TRANSACTIONS!$D$5:$D$244,TRANSACTIONS!$E$5:$E$244,"Sole Prop",TRANSACTIONS!$G$5:$G$244,"Tax/Remittance",TRANSACTIONS!$J$5:$J$244,$B6)+SUMIFS(TRANSACTIONS!$D$5:$D$244,TRANSACTIONS!$E$5:$E$244,"Corporation",TRANSACTIONS!$G$5:$G$244,"Tax/Remittance",TRANSACTIONS!$J$5:$J$244,$B6)) | M6: =(SUMIFS(TRANSACTIONS!$D$5:$D$244,TRANSACTIONS!$E$5:$E$244,"Sole Prop",TRANSACTIONS!$G$5:$G$244,"Owner Draw/Comp",TRANSACTIONS!$J$5:$J$244,$B6)+SUMIFS(TRANSACTIONS!$D$5:$D$244,TRANSACTIONS!$E$5:$E$244,"Corporation",TRANSACTIONS!$G$5:$G$244,"Owner Draw/Comp",TRANSACTIONS!$J$5:$J$244,$B6)) | N6: =(SUMIFS(TRANSACTIONS!$D$5:$D$244,TRANSACTIONS!$E$5:$E$244,"Sole Prop",TRANSACTIONS!$G$5:$G$244,"Capital Purchase",TRANSACTIONS!$J$5:$J$244,$B6)+SUMIFS(TRANSACTIONS!$D$5:$D$244,TRANSACTIONS!$E$5:$E$244,"Corporation",TRANSACTIONS!$G$5:$G$244,"Capital Purchase",TRANSACTIONS!$J$5:$J$244,$B6)) | O6: =(SUMIFS(TRANSACTIONS!$D$5:$D$244,TRANSACTIONS!$E$5:$E$244,"Sole Prop",TRANSACTIONS!$G$5:$G$244,"Financing",TRANSACTIONS!$J$5:$J$244,$B6)+SUMIFS(TRANSACTIONS!$D$5:$D$244,TRANSACTIONS!$E$5:$E$244,"Corporation",TRANSACTIONS!$G$5:$G$244,"Financing",TRANSACTIONS!$J$5:$J$244,$B6)) | P6: =C6+F6+I6+J6+K6+L6 | Q6: =SUMIFS(TRANSACTIONS!$D$5:$D$244,TRANSACTIONS!$E$5:$E$244,"Sole Prop",TRANSACTIONS!$J$5:$J$244,$B6)+SUMIFS(TRANSACTIONS!$D$5:$D$244,TRANSACTIONS!$E$5:$E$244,"Corporation",TRANSACTIONS!$J$5:$J$244,$B6) | R6: =SUMIFS(TRANSACTIONS!$D$5:$D$244,TRANSACTIONS!$E$5:$E$244,"Personal",TRANSACTIONS!$J$5:$J$244,$B6) | S6: =S5+SUMIFS(TRANSACTIONS!$D$5:$D$244,TRANSACTIONS!$E$5:$E$244,"Sole Prop",TRANSACTIONS!$J$5:$J$244,$B6) | T6: =T5+SUMIFS(TRANSACTIONS!$D$5:$D$244,TRANSACTIONS!$E$5:$E$244,"Corporation",TRANSACTIONS!$J$5:$J$244,$B6) | U6: =U5+R6 | V6: =S6+T6+U6
A7: Mar 2026 | B7: 202603 | C7: =SUMIFS(TRANSACTIONS!$D$5:$D$244,TRANSACTIONS!$E$5:$E$244,"Sole Prop",TRANSACTIONS!$G$5:$G$244,"Revenue",TRANSACTIONS!$J$5:$J$244,$B7) | D7: =-SUMIFS(TRANSACTIONS!$I$5:$I$244,TRANSACTIONS!$E$5:$E$244,"Sole Prop",TRANSACTIONS!$G$5:$G$244,"Revenue",TRANSACTIONS!$J$5:$J$244,$B7) | E7: =C7+D7 | F7: =SUMIFS(TRANSACTIONS!$D$5:$D$244,TRANSACTIONS!$E$5:$E$244,"Corporation",TRANSACTIONS!$G$5:$G$244,"Revenue",TRANSACTIONS!$J$5:$J$244,$B7) | G7: =-SUMIFS(TRANSACTIONS!$I$5:$I$244,TRANSACTIONS!$E$5:$E$244,"Corporation",TRANSACTIONS!$G$5:$G$244,"Revenue",TRANSACTIONS!$J$5:$J$244,$B7) | H7: =F7+G7 | I7: =(SUMIFS(TRANSACTIONS!$D$5:$D$244,TRANSACTIONS!$E$5:$E$244,"Sole Prop",TRANSACTIONS!$G$5:$G$244,"COGS",TRANSACTIONS!$J$5:$J$244,$B7)+SUMIFS(TRANSACTIONS!$D$5:$D$244,TRANSACTIONS!$E$5:$E$244,"Corporation",TRANSACTIONS!$G$5:$G$244,"COGS",TRANSACTIONS!$J$5:$J$244,$B7)) | J7: =(SUMIFS(TRANSACTIONS!$D$5:$D$244,TRANSACTIONS!$E$5:$E$244,"Sole Prop",TRANSACTIONS!$G$5:$G$244,"Operating Expense",TRANSACTIONS!$J$5:$J$244,$B7)+SUMIFS(TRANSACTIONS!$D$5:$D$244,TRANSACTIONS!$E$5:$E$244,"Corporation",TRANSACTIONS!$G$5:$G$244,"Operating Expense",TRANSACTIONS!$J$5:$J$244,$B7)) | K7: =(SUMIFS(TRANSACTIONS!$D$5:$D$244,TRANSACTIONS!$E$5:$E$244,"Sole Prop",TRANSACTIONS!$G$5:$G$244,"Payroll",TRANSACTIONS!$J$5:$J$244,$B7)+SUMIFS(TRANSACTIONS!$D$5:$D$244,TRANSACTIONS!$E$5:$E$244,"Corporation",TRANSACTIONS!$G$5:$G$244,"Payroll",TRANSACTIONS!$J$5:$J$244,$B7)) | L7: =(SUMIFS(TRANSACTIONS!$D$5:$D$244,TRANSACTIONS!$E$5:$E$244,"Sole Prop",TRANSACTIONS!$G$5:$G$244,"Tax/Remittance",TRANSACTIONS!$J$5:$J$244,$B7)+SUMIFS(TRANSACTIONS!$D$5:$D$244,TRANSACTIONS!$E$5:$E$244,"Corporation",TRANSACTIONS!$G$5:$G$244,"Tax/Remittance",TRANSACTIONS!$J$5:$J$244,$B7)) | M7: =(SUMIFS(TRANSACTIONS!$D$5:$D$244,TRANSACTIONS!$E$5:$E$244,"Sole Prop",TRANSACTIONS!$G$5:$G$244,"Owner Draw/Comp",TRANSACTIONS!$J$5:$J$244,$B7)+SUMIFS(TRANSACTIONS!$D$5:$D$244,TRANSACTIONS!$E$5:$E$244,"Corporation",TRANSACTIONS!$G$5:$G$244,"Owner Draw/Comp",TRANSACTIONS!$J$5:$J$244,$B7)) | N7: =(SUMIFS(TRANSACTIONS!$D$5:$D$244,TRANSACTIONS!$E$5:$E$244,"Sole Prop",TRANSACTIONS!$G$5:$G$244,"Capital Purchase",TRANSACTIONS!$J$5:$J$244,$B7)+SUMIFS(TRANSACTIONS!$D$5:$D$244,TRANSACTIONS!$E$5:$E$244,"Corporation",TRANSACTIONS!$G$5:$G$244,"Capital Purchase",TRANSACTIONS!$J$5:$J$244,$B7)) | O7: =(SUMIFS(TRANSACTIONS!$D$5:$D$244,TRANSACTIONS!$E$5:$E$244,"Sole Prop",TRANSACTIONS!$G$5:$G$244,"Financing",TRANSACTIONS!$J$5:$J$244,$B7)+SUMIFS(TRANSACTIONS!$D$5:$D$244,TRANSACTIONS!$E$5:$E$244,"Corporation",TRANSACTIONS!$G$5:$G$244,"Financing",TRANSACTIONS!$J$5:$J$244,$B7)) | P7: =C7+F7+I7+J7+K7+L7 | Q7: =SUMIFS(TRANSACTIONS!$D$5:$D$244,TRANSACTIONS!$E$5:$E$244,"Sole Prop",TRANSACTIONS!$J$5:$J$244,$B7)+SUMIFS(TRANSACTIONS!$D$5:$D$244,TRANSACTIONS!$E$5:$E$244,"Corporation",TRANSACTIONS!$J$5:$J$244,$B7) | R7: =SUMIFS(TRANSACTIONS!$D$5:$D$244,TRANSACTIONS!$E$5:$E$244,"Personal",TRANSACTIONS!$J$5:$J$244,$B7) | S7: =S6+SUMIFS(TRANSACTIONS!$D$5:$D$244,TRANSACTIONS!$E$5:$E$244,"Sole Prop",TRANSACTIONS!$J$5:$J$244,$B7) | T7: =T6+SUMIFS(TRANSACTIONS!$D$5:$D$244,TRANSACTIONS!$E$5:$E$244,"Corporation",TRANSACTIONS!$J$5:$J$244,$B7) | U7: =U6+R7 | V7: =S7+T7+U7
A8: Apr 2026 | B8: 202604 | C8: =SUMIFS(TRANSACTIONS!$D$5:$D$244,TRANSACTIONS!$E$5:$E$244,"Sole Prop",TRANSACTIONS!$G$5:$G$244,"Revenue",TRANSACTIONS!$J$5:$J$244,$B8) | D8: =-SUMIFS(TRANSACTIONS!$I$5:$I$244,TRANSACTIONS!$E$5:$E$244,"Sole Prop",TRANSACTIONS!$G$5:$G$244,"Revenue",TRANSACTIONS!$J$5:$J$244,$B8) | E8: =C8+D8 | F8: =SUMIFS(TRANSACTIONS!$D$5:$D$244,TRANSACTIONS!$E$5:$E$244,"Corporation",TRANSACTIONS!$G$5:$G$244,"Revenue",TRANSACTIONS!$J$5:$J$244,$B8) | G8: =-SUMIFS(TRANSACTIONS!$I$5:$I$244,TRANSACTIONS!$E$5:$E$244,"Corporation",TRANSACTIONS!$G$5:$G$244,"Revenue",TRANSACTIONS!$J$5:$J$244,$B8) | H8: =F8+G8 | I8: =(SUMIFS(TRANSACTIONS!$D$5:$D$244,TRANSACTIONS!$E$5:$E$244,"Sole Prop",TRANSACTIONS!$G$5:$G$244,"COGS",TRANSACTIONS!$J$5:$J$244,$B8)+SUMIFS(TRANSACTIONS!$D$5:$D$244,TRANSACTIONS!$E$5:$E$244,"Corporation",TRANSACTIONS!$G$5:$G$244,"COGS",TRANSACTIONS!$J$5:$J$244,$B8)) | J8: =(SUMIFS(TRANSACTIONS!$D$5:$D$244,TRANSACTIONS!$E$5:$E$244,"Sole Prop",TRANSACTIONS!$G$5:$G$244,"Operating Expense",TRANSACTIONS!$J$5:$J$244,$B8)+SUMIFS(TRANSACTIONS!$D$5:$D$244,TRANSACTIONS!$E$5:$E$244,"Corporation",TRANSACTIONS!$G$5:$G$244,"Operating Expense",TRANSACTIONS!$J$5:$J$244,$B8)) | K8: =(SUMIFS(TRANSACTIONS!$D$5:$D$244,TRANSACTIONS!$E$5:$E$244,"Sole Prop",TRANSACTIONS!$G$5:$G$244,"Payroll",TRANSACTIONS!$J$5:$J$244,$B8)+SUMIFS(TRANSACTIONS!$D$5:$D$244,TRANSACTIONS!$E$5:$E$244,"Corporation",TRANSACTIONS!$G$5:$G$244,"Payroll",TRANSACTIONS!$J$5:$J$244,$B8)) | L8: =(SUMIFS(TRANSACTIONS!$D$5:$D$244,TRANSACTIONS!$E$5:$E$244,"Sole Prop",TRANSACTIONS!$G$5:$G$244,"Tax/Remittance",TRANSACTIONS!$J$5:$J$244,$B8)+SUMIFS(TRANSACTIONS!$D$5:$D$244,TRANSACTIONS!$E$5:$E$244,"Corporation",TRANSACTIONS!$G$5:$G$244,"Tax/Remittance",TRANSACTIONS!$J$5:$J$244,$B8)) | M8: =(SUMIFS(TRANSACTIONS!$D$5:$D$244,TRANSACTIONS!$E$5:$E$244,"Sole Prop",TRANSACTIONS!$G$5:$G$244,"Owner Draw/Comp",TRANSACTIONS!$J$5:$J$244,$B8)+SUMIFS(TRANSACTIONS!$D$5:$D$244,TRANSACTIONS!$E$5:$E$244,"Corporation",TRANSACTIONS!$G$5:$G$244,"Owner Draw/Comp",TRANSACTIONS!$J$5:$J$244,$B8)) | N8: =(SUMIFS(TRANSACTIONS!$D$5:$D$244,TRANSACTIONS!$E$5:$E$244,"Sole Prop",TRANSACTIONS!$G$5:$G$244,"Capital Purchase",TRANSACTIONS!$J$5:$J$244,$B8)+SUMIFS(TRANSACTIONS!$D$5:$D$244,TRANSACTIONS!$E$5:$E$244,"Corporation",TRANSACTIONS!$G$5:$G$244,"Capital Purchase",TRANSACTIONS!$J$5:$J$244,$B8)) | O8: =(SUMIFS(TRANSACTIONS!$D$5:$D$244,TRANSACTIONS!$E$5:$E$244,"Sole Prop",TRANSACTIONS!$G$5:$G$244,"Financing",TRANSACTIONS!$J$5:$J$244,$B8)+SUMIFS(TRANSACTIONS!$D$5:$D$244,TRANSACTIONS!$E$5:$E$244,"Corporation",TRANSACTIONS!$G$5:$G$244,"Financing",TRANSACTIONS!$J$5:$J$244,$B8)) | P8: =C8+F8+I8+J8+K8+L8 | Q8: =SUMIFS(TRANSACTIONS!$D$5:$D$244,TRANSACTIONS!$E$5:$E$244,"Sole Prop",TRANSACTIONS!$J$5:$J$244,$B8)+SUMIFS(TRANSACTIONS!$D$5:$D$244,TRANSACTIONS!$E$5:$E$244,"Corporation",TRANSACTIONS!$J$5:$J$244,$B8) | R8: =SUMIFS(TRANSACTIONS!$D$5:$D$244,TRANSACTIONS!$E$5:$E$244,"Personal",TRANSACTIONS!$J$5:$J$244,$B8) | S8: =S7+SUMIFS(TRANSACTIONS!$D$5:$D$244,TRANSACTIONS!$E$5:$E$244,"Sole Prop",TRANSACTIONS!$J$5:$J$244,$B8) | T8: =T7+SUMIFS(TRANSACTIONS!$D$5:$D$244,TRANSACTIONS!$E$5:$E$244,"Corporation",TRANSACTIONS!$J$5:$J$244,$B8) | U8: =U7+R8 | V8: =S8+T8+U8
A9: May 2026 | B9: 202605 | C9: =SUMIFS(TRANSACTIONS!$D$5:$D$244,TRANSACTIONS!$E$5:$E$244,"Sole Prop",TRANSACTIONS!$G$5:$G$244,"Revenue",TRANSACTIONS!$J$5:$J$244,$B9) | D9: =-SUMIFS(TRANSACTIONS!$I$5:$I$244,TRANSACTIONS!$E$5:$E$244,"Sole Prop",TRANSACTIONS!$G$5:$G$244,"Revenue",TRANSACTIONS!$J$5:$J$244,$B9) | E9: =C9+D9 | F9: =SUMIFS(TRANSACTIONS!$D$5:$D$244,TRANSACTIONS!$E$5:$E$244,"Corporation",TRANSACTIONS!$G$5:$G$244,"Revenue",TRANSACTIONS!$J$5:$J$244,$B9) | G9: =-SUMIFS(TRANSACTIONS!$I$5:$I$244,TRANSACTIONS!$E$5:$E$244,"Corporation",TRANSACTIONS!$G$5:$G$244,"Revenue",TRANSACTIONS!$J$5:$J$244,$B9) | H9: =F9+G9 | I9: =(SUMIFS(TRANSACTIONS!$D$5:$D$244,TRANSACTIONS!$E$5:$E$244,"Sole Prop",TRANSACTIONS!$G$5:$G$244,"COGS",TRANSACTIONS!$J$5:$J$244,$B9)+SUMIFS(TRANSACTIONS!$D$5:$D$244,TRANSACTIONS!$E$5:$E$244,"Corporation",TRANSACTIONS!$G$5:$G$244,"COGS",TRANSACTIONS!$J$5:$J$244,$B9)) | J9: =(SUMIFS(TRANSACTIONS!$D$5:$D$244,TRANSACTIONS!$E$5:$E$244,"Sole Prop",TRANSACTIONS!$G$5:$G$244,"Operating Expense",TRANSACTIONS!$J$5:$J$244,$B9)+SUMIFS(TRANSACTIONS!$D$5:$D$244,TRANSACTIONS!$E$5:$E$244,"Corporation",TRANSACTIONS!$G$5:$G$244,"Operating Expense",TRANSACTIONS!$J$5:$J$244,$B9)) | K9: =(SUMIFS(TRANSACTIONS!$D$5:$D$244,TRANSACTIONS!$E$5:$E$244,"Sole Prop",TRANSACTIONS!$G$5:$G$244,"Payroll",TRANSACTIONS!$J$5:$J$244,$B9)+SUMIFS(TRANSACTIONS!$D$5:$D$244,TRANSACTIONS!$E$5:$E$244,"Corporation",TRANSACTIONS!$G$5:$G$244,"Payroll",TRANSACTIONS!$J$5:$J$244,$B9)) | L9: =(SUMIFS(TRANSACTIONS!$D$5:$D$244,TRANSACTIONS!$E$5:$E$244,"Sole Prop",TRANSACTIONS!$G$5:$G$244,"Tax/Remittance",TRANSACTIONS!$J$5:$J$244,$B9)+SUMIFS(TRANSACTIONS!$D$5:$D$244,TRANSACTIONS!$E$5:$E$244,"Corporation",TRANSACTIONS!$G$5:$G$244,"Tax/Remittance",TRANSACTIONS!$J$5:$J$244,$B9)) | M9: =(SUMIFS(TRANSACTIONS!$D$5:$D$244,TRANSACTIONS!$E$5:$E$244,"Sole Prop",TRANSACTIONS!$G$5:$G$244,"Owner Draw/Comp",TRANSACTIONS!$J$5:$J$244,$B9)+SUMIFS(TRANSACTIONS!$D$5:$D$244,TRANSACTIONS!$E$5:$E$244,"Corporation",TRANSACTIONS!$G$5:$G$244,"Owner Draw/Comp",TRANSACTIONS!$J$5:$J$244,$B9)) | N9: =(SUMIFS(TRANSACTIONS!$D$5:$D$244,TRANSACTIONS!$E$5:$E$244,"Sole Prop",TRANSACTIONS!$G$5:$G$244,"Capital Purchase",TRANSACTIONS!$J$5:$J$244,$B9)+SUMIFS(TRANSACTIONS!$D$5:$D$244,TRANSACTIONS!$E$5:$E$244,"Corporation",TRANSACTIONS!$G$5:$G$244,"Capital Purchase",TRANSACTIONS!$J$5:$J$244,$B9)) | O9: =(SUMIFS(TRANSACTIONS!$D$5:$D$244,TRANSACTIONS!$E$5:$E$244,"Sole Prop",TRANSACTIONS!$G$5:$G$244,"Financing",TRANSACTIONS!$J$5:$J$244,$B9)+SUMIFS(TRANSACTIONS!$D$5:$D$244,TRANSACTIONS!$E$5:$E$244,"Corporation",TRANSACTIONS!$G$5:$G$244,"Financing",TRANSACTIONS!$J$5:$J$244,$B9)) | P9: =C9+F9+I9+J9+K9+L9 | Q9: =SUMIFS(TRANSACTIONS!$D$5:$D$244,TRANSACTIONS!$E$5:$E$244,"Sole Prop",TRANSACTIONS!$J$5:$J$244,$B9)+SUMIFS(TRANSACTIONS!$D$5:$D$244,TRANSACTIONS!$E$5:$E$244,"Corporation",TRANSACTIONS!$J$5:$J$244,$B9) | R9: =SUMIFS(TRANSACTIONS!$D$5:$D$244,TRANSACTIONS!$E$5:$E$244,"Personal",TRANSACTIONS!$J$5:$J$244,$B9) | S9: =S8+SUMIFS(TRANSACTIONS!$D$5:$D$244,TRANSACTIONS!$E$5:$E$244,"Sole Prop",TRANSACTIONS!$J$5:$J$244,$B9) | T9: =T8+SUMIFS(TRANSACTIONS!$D$5:$D$244,TRANSACTIONS!$E$5:$E$244,"Corporation",TRANSACTIONS!$J$5:$J$244,$B9) | U9: =U8+R9 | V9: =S9+T9+U9
A10: Jun 2026 | B10: 202606 | C10: =SUMIFS(TRANSACTIONS!$D$5:$D$244,TRANSACTIONS!$E$5:$E$244,"Sole Prop",TRANSACTIONS!$G$5:$G$244,"Revenue",TRANSACTIONS!$J$5:$J$244,$B10) | D10: =-SUMIFS(TRANSACTIONS!$I$5:$I$244,TRANSACTIONS!$E$5:$E$244,"Sole Prop",TRANSACTIONS!$G$5:$G$244,"Revenue",TRANSACTIONS!$J$5:$J$244,$B10) | E10: =C10+D10 | F10: =SUMIFS(TRANSACTIONS!$D$5:$D$244,TRANSACTIONS!$E$5:$E$244,"Corporation",TRANSACTIONS!$G$5:$G$244,"Revenue",TRANSACTIONS!$J$5:$J$244,$B10) | G10: =-SUMIFS(TRANSACTIONS!$I$5:$I$244,TRANSACTIONS!$E$5:$E$244,"Corporation",TRANSACTIONS!$G$5:$G$244,"Revenue",TRANSACTIONS!$J$5:$J$244,$B10) | H10: =F10+G10 | I10: =(SUMIFS(TRANSACTIONS!$D$5:$D$244,TRANSACTIONS!$E$5:$E$244,"Sole Prop",TRANSACTIONS!$G$5:$G$244,"COGS",TRANSACTIONS!$J$5:$J$244,$B10)+SUMIFS(TRANSACTIONS!$D$5:$D$244,TRANSACTIONS!$E$5:$E$244,"Corporation",TRANSACTIONS!$G$5:$G$244,"COGS",TRANSACTIONS!$J$5:$J$244,$B10)) | J10: =(SUMIFS(TRANSACTIONS!$D$5:$D$244,TRANSACTIONS!$E$5:$E$244,"Sole Prop",TRANSACTIONS!$G$5:$G$244,"Operating Expense",TRANSACTIONS!$J$5:$J$244,$B10)+SUMIFS(TRANSACTIONS!$D$5:$D$244,TRANSACTIONS!$E$5:$E$244,"Corporation",TRANSACTIONS!$G$5:$G$244,"Operating Expense",TRANSACTIONS!$J$5:$J$244,$B10)) | K10: =(SUMIFS(TRANSACTIONS!$D$5:$D$244,TRANSACTIONS!$E$5:$E$244,"Sole Prop",TRANSACTIONS!$G$5:$G$244,"Payroll",TRANSACTIONS!$J$5:$J$244,$B10)+SUMIFS(TRANSACTIONS!$D$5:$D$244,TRANSACTIONS!$E$5:$E$244,"Corporation",TRANSACTIONS!$G$5:$G$244,"Payroll",TRANSACTIONS!$J$5:$J$244,$B10)) | L10: =(SUMIFS(TRANSACTIONS!$D$5:$D$244,TRANSACTIONS!$E$5:$E$244,"Sole Prop",TRANSACTIONS!$G$5:$G$244,"Tax/Remittance",TRANSACTIONS!$J$5:$J$244,$B10)+SUMIFS(TRANSACTIONS!$D$5:$D$244,TRANSACTIONS!$E$5:$E$244,"Corporation",TRANSACTIONS!$G$5:$G$244,"Tax/Remittance",TRANSACTIONS!$J$5:$J$244,$B10)) | M10: =(SUMIFS(TRANSACTIONS!$D$5:$D$244,TRANSACTIONS!$E$5:$E$244,"Sole Prop",TRANSACTIONS!$G$5:$G$244,"Owner Draw/Comp",TRANSACTIONS!$J$5:$J$244,$B10)+SUMIFS(TRANSACTIONS!$D$5:$D$244,TRANSACTIONS!$E$5:$E$244,"Corporation",TRANSACTIONS!$G$5:$G$244,"Owner Draw/Comp",TRANSACTIONS!$J$5:$J$244,$B10)) | N10: =(SUMIFS(TRANSACTIONS!$D$5:$D$244,TRANSACTIONS!$E$5:$E$244,"Sole Prop",TRANSACTIONS!$G$5:$G$244,"Capital Purchase",TRANSACTIONS!$J$5:$J$244,$B10)+SUMIFS(TRANSACTIONS!$D$5:$D$244,TRANSACTIONS!$E$5:$E$244,"Corporation",TRANSACTIONS!$G$5:$G$244,"Capital Purchase",TRANSACTIONS!$J$5:$J$244,$B10)) | O10: =(SUMIFS(TRANSACTIONS!$D$5:$D$244,TRANSACTIONS!$E$5:$E$244,"Sole Prop",TRANSACTIONS!$G$5:$G$244,"Financing",TRANSACTIONS!$J$5:$J$244,$B10)+SUMIFS(TRANSACTIONS!$D$5:$D$244,TRANSACTIONS!$E$5:$E$244,"Corporation",TRANSACTIONS!$G$5:$G$244,"Financing",TRANSACTIONS!$J$5:$J$244,$B10)) | P10: =C10+F10+I10+J10+K10+L10 | Q10: =SUMIFS(TRANSACTIONS!$D$5:$D$244,TRANSACTIONS!$E$5:$E$244,"Sole Prop",TRANSACTIONS!$J$5:$J$244,$B10)+SUMIFS(TRANSACTIONS!$D$5:$D$244,TRANSACTIONS!$E$5:$E$244,"Corporation",TRANSACTIONS!$J$5:$J$244,$B10) | R10: =SUMIFS(TRANSACTIONS!$D$5:$D$244,TRANSACTIONS!$E$5:$E$244,"Personal",TRANSACTIONS!$J$5:$J$244,$B10) | S10: =S9+SUMIFS(TRANSACTIONS!$D$5:$D$244,TRANSACTIONS!$E$5:$E$244,"Sole Prop",TRANSACTIONS!$J$5:$J$244,$B10) | T10: =T9+SUMIFS(TRANSACTIONS!$D$5:$D$244,TRANSACTIONS!$E$5:$E$244,"Corporation",TRANSACTIONS!$J$5:$J$244,$B10) | U10: =U9+R10 | V10: =S10+T10+U10
A11: Jul 2026 | B11: 202607 | C11: =SUMIFS(TRANSACTIONS!$D$5:$D$244,TRANSACTIONS!$E$5:$E$244,"Sole Prop",TRANSACTIONS!$G$5:$G$244,"Revenue",TRANSACTIONS!$J$5:$J$244,$B11) | D11: =-SUMIFS(TRANSACTIONS!$I$5:$I$244,TRANSACTIONS!$E$5:$E$244,"Sole Prop",TRANSACTIONS!$G$5:$G$244,"Revenue",TRANSACTIONS!$J$5:$J$244,$B11) | E11: =C11+D11 | F11: =SUMIFS(TRANSACTIONS!$D$5:$D$244,TRANSACTIONS!$E$5:$E$244,"Corporation",TRANSACTIONS!$G$5:$G$244,"Revenue",TRANSACTIONS!$J$5:$J$244,$B11) | G11: =-SUMIFS(TRANSACTIONS!$I$5:$I$244,TRANSACTIONS!$E$5:$E$244,"Corporation",TRANSACTIONS!$G$5:$G$244,"Revenue",TRANSACTIONS!$J$5:$J$244,$B11) | H11: =F11+G11 | I11: =(SUMIFS(TRANSACTIONS!$D$5:$D$244,TRANSACTIONS!$E$5:$E$244,"Sole Prop",TRANSACTIONS!$G$5:$G$244,"COGS",TRANSACTIONS!$J$5:$J$244,$B11)+SUMIFS(TRANSACTIONS!$D$5:$D$244,TRANSACTIONS!$E$5:$E$244,"Corporation",TRANSACTIONS!$G$5:$G$244,"COGS",TRANSACTIONS!$J$5:$J$244,$B11)) | J11: =(SUMIFS(TRANSACTIONS!$D$5:$D$244,TRANSACTIONS!$E$5:$E$244,"Sole Prop",TRANSACTIONS!$G$5:$G$244,"Operating Expense",TRANSACTIONS!$J$5:$J$244,$B11)+SUMIFS(TRANSACTIONS!$D$5:$D$244,TRANSACTIONS!$E$5:$E$244,"Corporation",TRANSACTIONS!$G$5:$G$244,"Operating Expense",TRANSACTIONS!$J$5:$J$244,$B11)) | K11: =(SUMIFS(TRANSACTIONS!$D$5:$D$244,TRANSACTIONS!$E$5:$E$244,"Sole Prop",TRANSACTIONS!$G$5:$G$244,"Payroll",TRANSACTIONS!$J$5:$J$244,$B11)+SUMIFS(TRANSACTIONS!$D$5:$D$244,TRANSACTIONS!$E$5:$E$244,"Corporation",TRANSACTIONS!$G$5:$G$244,"Payroll",TRANSACTIONS!$J$5:$J$244,$B11)) | L11: =(SUMIFS(TRANSACTIONS!$D$5:$D$244,TRANSACTIONS!$E$5:$E$244,"Sole Prop",TRANSACTIONS!$G$5:$G$244,"Tax/Remittance",TRANSACTIONS!$J$5:$J$244,$B11)+SUMIFS(TRANSACTIONS!$D$5:$D$244,TRANSACTIONS!$E$5:$E$244,"Corporation",TRANSACTIONS!$G$5:$G$244,"Tax/Remittance",TRANSACTIONS!$J$5:$J$244,$B11)) | M11: =(SUMIFS(TRANSACTIONS!$D$5:$D$244,TRANSACTIONS!$E$5:$E$244,"Sole Prop",TRANSACTIONS!$G$5:$G$244,"Owner Draw/Comp",TRANSACTIONS!$J$5:$J$244,$B11)+SUMIFS(TRANSACTIONS!$D$5:$D$244,TRANSACTIONS!$E$5:$E$244,"Corporation",TRANSACTIONS!$G$5:$G$244,"Owner Draw/Comp",TRANSACTIONS!$J$5:$J$244,$B11)) | N11: =(SUMIFS(TRANSACTIONS!$D$5:$D$244,TRANSACTIONS!$E$5:$E$244,"Sole Prop",TRANSACTIONS!$G$5:$G$244,"Capital Purchase",TRANSACTIONS!$J$5:$J$244,$B11)+SUMIFS(TRANSACTIONS!$D$5:$D$244,TRANSACTIONS!$E$5:$E$244,"Corporation",TRANSACTIONS!$G$5:$G$244,"Capital Purchase",TRANSACTIONS!$J$5:$J$244,$B11)) | O11: =(SUMIFS(TRANSACTIONS!$D$5:$D$244,TRANSACTIONS!$E$5:$E$244,"Sole Prop",TRANSACTIONS!$G$5:$G$244,"Financing",TRANSACTIONS!$J$5:$J$244,$B11)+SUMIFS(TRANSACTIONS!$D$5:$D$244,TRANSACTIONS!$E$5:$E$244,"Corporation",TRANSACTIONS!$G$5:$G$244,"Financing",TRANSACTIONS!$J$5:$J$244,$B11)) | P11: =C11+F11+I11+J11+K11+L11 | Q11: =SUMIFS(TRANSACTIONS!$D$5:$D$244,TRANSACTIONS!$E$5:$E$244,"Sole Prop",TRANSACTIONS!$J$5:$J$244,$B11)+SUMIFS(TRANSACTIONS!$D$5:$D$244,TRANSACTIONS!$E$5:$E$244,"Corporation",TRANSACTIONS!$J$5:$J$244,$B11) | R11: =SUMIFS(TRANSACTIONS!$D$5:$D$244,TRANSACTIONS!$E$5:$E$244,"Personal",TRANSACTIONS!$J$5:$J$244,$B11) | S11: =S10+SUMIFS(TRANSACTIONS!$D$5:$D$244,TRANSACTIONS!$E$5:$E$244,"Sole Prop",TRANSACTIONS!$J$5:$J$244,$B11) | T11: =T10+SUMIFS(TRANSACTIONS!$D$5:$D$244,TRANSACTIONS!$E$5:$E$244,"Corporation",TRANSACTIONS!$J$5:$J$244,$B11) | U11: =U10+R11 | V11: =S11+T11+U11
A12: Aug 2026 | B12: 202608 | C12: =SUMIFS(TRANSACTIONS!$D$5:$D$244,TRANSACTIONS!$E$5:$E$244,"Sole Prop",TRANSACTIONS!$G$5:$G$244,"Revenue",TRANSACTIONS!$J$5:$J$244,$B12) | D12: =-SUMIFS(TRANSACTIONS!$I$5:$I$244,TRANSACTIONS!$E$5:$E$244,"Sole Prop",TRANSACTIONS!$G$5:$G$244,"Revenue",TRANSACTIONS!$J$5:$J$244,$B12) | E12: =C12+D12 | F12: =SUMIFS(TRANSACTIONS!$D$5:$D$244,TRANSACTIONS!$E$5:$E$244,"Corporation",TRANSACTIONS!$G$5:$G$244,"Revenue",TRANSACTIONS!$J$5:$J$244,$B12) | G12: =-SUMIFS(TRANSACTIONS!$I$5:$I$244,TRANSACTIONS!$E$5:$E$244,"Corporation",TRANSACTIONS!$G$5:$G$244,"Revenue",TRANSACTIONS!$J$5:$J$244,$B12) | H12: =F12+G12 | I12: =(SUMIFS(TRANSACTIONS!$D$5:$D$244,TRANSACTIONS!$E$5:$E$244,"Sole Prop",TRANSACTIONS!$G$5:$G$244,"COGS",TRANSACTIONS!$J$5:$J$244,$B12)+SUMIFS(TRANSACTIONS!$D$5:$D$244,TRANSACTIONS!$E$5:$E$244,"Corporation",TRANSACTIONS!$G$5:$G$244,"COGS",TRANSACTIONS!$J$5:$J$244,$B12)) | J12: =(SUMIFS(TRANSACTIONS!$D$5:$D$244,TRANSACTIONS!$E$5:$E$244,"Sole Prop",TRANSACTIONS!$G$5:$G$244,"Operating Expense",TRANSACTIONS!$J$5:$J$244,$B12)+SUMIFS(TRANSACTIONS!$D$5:$D$244,TRANSACTIONS!$E$5:$E$244,"Corporation",TRANSACTIONS!$G$5:$G$244,"Operating Expense",TRANSACTIONS!$J$5:$J$244,$B12)) | K12: =(SUMIFS(TRANSACTIONS!$D$5:$D$244,TRANSACTIONS!$E$5:$E$244,"Sole Prop",TRANSACTIONS!$G$5:$G$244,"Payroll",TRANSACTIONS!$J$5:$J$244,$B12)+SUMIFS(TRANSACTIONS!$D$5:$D$244,TRANSACTIONS!$E$5:$E$244,"Corporation",TRANSACTIONS!$G$5:$G$244,"Payroll",TRANSACTIONS!$J$5:$J$244,$B12)) | L12: =(SUMIFS(TRANSACTIONS!$D$5:$D$244,TRANSACTIONS!$E$5:$E$244,"Sole Prop",TRANSACTIONS!$G$5:$G$244,"Tax/Remittance",TRANSACTIONS!$J$5:$J$244,$B12)+SUMIFS(TRANSACTIONS!$D$5:$D$244,TRANSACTIONS!$E$5:$E$244,"Corporation",TRANSACTIONS!$G$5:$G$244,"Tax/Remittance",TRANSACTIONS!$J$5:$J$244,$B12)) | M12: =(SUMIFS(TRANSACTIONS!$D$5:$D$244,TRANSACTIONS!$E$5:$E$244,"Sole Prop",TRANSACTIONS!$G$5:$G$244,"Owner Draw/Comp",TRANSACTIONS!$J$5:$J$244,$B12)+SUMIFS(TRANSACTIONS!$D$5:$D$244,TRANSACTIONS!$E$5:$E$244,"Corporation",TRANSACTIONS!$G$5:$G$244,"Owner Draw/Comp",TRANSACTIONS!$J$5:$J$244,$B12)) | N12: =(SUMIFS(TRANSACTIONS!$D$5:$D$244,TRANSACTIONS!$E$5:$E$244,"Sole Prop",TRANSACTIONS!$G$5:$G$244,"Capital Purchase",TRANSACTIONS!$J$5:$J$244,$B12)+SUMIFS(TRANSACTIONS!$D$5:$D$244,TRANSACTIONS!$E$5:$E$244,"Corporation",TRANSACTIONS!$G$5:$G$244,"Capital Purchase",TRANSACTIONS!$J$5:$J$244,$B12)) | O12: =(SUMIFS(TRANSACTIONS!$D$5:$D$244,TRANSACTIONS!$E$5:$E$244,"Sole Prop",TRANSACTIONS!$G$5:$G$244,"Financing",TRANSACTIONS!$J$5:$J$244,$B12)+SUMIFS(TRANSACTIONS!$D$5:$D$244,TRANSACTIONS!$E$5:$E$244,"Corporation",TRANSACTIONS!$G$5:$G$244,"Financing",TRANSACTIONS!$J$5:$J$244,$B12)) | P12: =C12+F12+I12+J12+K12+L12 | Q12: =SUMIFS(TRANSACTIONS!$D$5:$D$244,TRANSACTIONS!$E$5:$E$244,"Sole Prop",TRANSACTIONS!$J$5:$J$244,$B12)+SUMIFS(TRANSACTIONS!$D$5:$D$244,TRANSACTIONS!$E$5:$E$244,"Corporation",TRANSACTIONS!$J$5:$J$244,$B12) | R12: =SUMIFS(TRANSACTIONS!$D$5:$D$244,TRANSACTIONS!$E$5:$E$244,"Personal",TRANSACTIONS!$J$5:$J$244,$B12) | S12: =S11+SUMIFS(TRANSACTIONS!$D$5:$D$244,TRANSACTIONS!$E$5:$E$244,"Sole Prop",TRANSACTIONS!$J$5:$J$244,$B12) | T12: =T11+SUMIFS(TRANSACTIONS!$D$5:$D$244,TRANSACTIONS!$E$5:$E$244,"Corporation",TRANSACTIONS!$J$5:$J$244,$B12) | U12: =U11+R12 | V12: =S12+T12+U12
